Workbook

Sheet BASE
A1: descricao | B1: tipo_produto | C1: marca | D1: categoria | E1: sub_categoria
A2: ABOBORA CABOTIA | B2: ABOBORA | D2: {=XLOOKUP(B2,CONFIG!A:A,CONFIG!B:B)} -> ALIMENTOS | E2: LEGUMES
A3: ABOBORA CABOTIA KG | B3: ABOBORA | D3: {=XLOOKUP(B3,CONFIG!A:A,CONFIG!B:B)} -> ALIMENTOS | E3: LEGUMES
A4: ABOBORA PAULIST | B4: ABOBORA | D4: {=XLOOKUP(B4,CONFIG!A:A,CONFIG!B:B)} -> ALIMENTOS | E4: LEGUMES
A5: ABS INTIMUS TRI | B5: ABSORVENTE | D5: {=XLOOKUP(B5,CONFIG!A:A,CONFIG!B:B)} -> CORPO E BANHO
A6: ABSORVENTE POISE PRO | B6: ABSORVENTE | D6: {=XLOOKUP(B6,CONFIG!A:A,CONFIG!B:B)} -> CORPO E BANHO
A7: ACEM KG | B7: ACEM | D7: {=XLOOKUP(B7,CONFIG!A:A,CONFIG!B:B)} -> ALIMENTOS | E7: CARNES
A8: AC REF UNIAO 1KG | B8: ACUCAR REFINADO | C8: UNIAO | D8: {=XLOOKUP(B8,CONFIG!A:A,CONFIG!B:B)} -> ALIMENTOS
A9: ACUCAR CRISTAL DELTA | B9: ACUCAR CRISTAL | C9: DELTA | D9: {=XLOOKUP(B9,CONFIG!A:A,CONFIG!B:B)} -> ALIMENTOS
A10: ACUCAR MASCAVO VITAPAO 500GR | B10: ACUCAR MASCAVO | C10: VITAPAO | D10: {=XLOOKUP(B10,CONFIG!A:A,CONFIG!B:B)} -> ALIMENTOS
A11: ACUC CR DELTA 2KG | B11: ACUCAR CRISTAL | C11: DELTA | D11: {=XLOOKUP(B11,CONFIG!A:A,CONFIG!B:B)} -> ALIMENTOS
A12: ADESIVOS STICKERS U.N | B12: ADESIVO | D12: {=XLOOKUP(B12,CONFIG!A:A,CONFIG!B:B)} -> OUTROS
A13: AG CRYSTAL C/G 500ML | B13: AGUA COM GAS | D13: {=XLOOKUP(B13,CONFIG!A:A,CONFIG!B:B)} -> BEBIDAS
A14: AG MIN CRYST C/G 500 | B14: AGUA COM GAS | D14: {=XLOOKUP(B14,CONFIG!A:A,CONFIG!B:B)} -> BEBIDAS
A15: AGUA MIN CRYSTA | B15: AGUA COM GAS | D15: {=XLOOKUP(B15,CONFIG!A:A,CONFIG!B:B)} -> BEBIDAS
A16: AGUA MIN CRYSTAL C/G | B16: AGUA COM GAS | D16: {=XLOOKUP(B16,CONFIG!A:A,CONFIG!B:B)} -> BEBIDAS
A17: AGUA MIN MINEIRO 500 | B17: AGUA COM GAS | D17: {=XLOOKUP(B17,CONFIG!A:A,CONFIG!B:B)} -> BEBIDAS
A18: AGUA SANIT CLASSIC 2LI | B18: DESINFETANTE | D18: {=XLOOKUP(B18,CONFIG!A:A,CONFIG!B:B)} -> LIMPEZA
A19: ALCATRA | B19: ALCATRA | D19: {=XLOOKUP(B19,CONFIG!A:A,CONFIG!B:B)} -> ALIMENTOS | E19: CARNES
A20: ALCATRA KG | B20: ALCATRA | D20: {=XLOOKUP(B20,CONFIG!A:A,CONFIG!B:B)} -> ALIMENTOS
A21: ALFACE C | B21: ALFACE | D21: {=XLOOKUP(B21,CONFIG!A:A,CONFIG!B:B)} -> ALIMENTOS | E21: VERDURA
A22: ALFACE CRESPA HIDROP | B22: ALFACE | D22: {=XLOOKUP(B22,CONFIG!A:A,CONFIG!B:B)} -> ALIMENTOS
A23: ALFACE ROMANA CAIXA QUALITY | B23: ALHO | D23: {=XLOOKUP(B23,CONFIG!A:A,CONFIG!B:B)} -> ALIMENTOS
A24: ALHO CAMPEAO 200G TRITURADO | B24: ALHO | D24: {=XLOOKUP(B24,CONFIG!A:A,CONFIG!B:B)} -> ALIMENTOS
A25: ALHO KG | B25: ALHO | D25: {=XLOOKUP(B25,CONFIG!A:A,CONFIG!B:B)} -> ALIMENTOS
A26: ALHO -NACIONAL | B26: ALHO | D26: {=XLOOKUP(B26,CONFIG!A:A,CONFIG!B:B)} -> ALIMENTOS
A27: ALHO NACIONAL GRAUDO | B27: ALHO | D27: {=XLOOKUP(B27,CONFIG!A:A,CONFIG!B:B)} -> ALIMENTOS
A28: ALHO PIRATA DESID 20 | B28: ALHO | D28: {=XLOOKUP(B28,CONFIG!A:A,CONFIG!B:B)} -> ALIMENTOS
A29: ALHO PORO BELGUSTO | B29: ALHO | D29: {=XLOOKUP(B29,CONFIG!A:A,CONFIG!B:B)} -> ALIMENTOS
A30: ALHO ROXINHO TR | B30: ALHO | D30: {=XLOOKUP(B30,CONFIG!A:A,CONFIG!B:B)} -> ALIMENTOS
A31: ALMONDEGA BOVINA PT 900G SADIA | B31: ALMONDEGA | C31: SADIA | D31: {=XLOOKUP(B31,CONFIG!A:A,CONFIG!B:B)} -> ALIMENTOS | E31: CARNES
A32: ALVEJ PO VANISH SACHE 400GR PINK | B32: VANISH | C32: VANISH | D32: {=XLOOKUP(B32,CONFIG!A:A,CONFIG!B:B)} -> LIMPEZA
A33: AMAC ROUPA CONC DOWNY GF 1 5L PRIMAVERA | B33: AMACIANTE | C33: DOWNY | D33: {=XLOOKUP(B33,CONFIG!A:A,CONFIG!B:B)} -> LIMPEZA
A34: AMEIXA NACIONAL KG | B34: AMEIXA | D34: {=XLOOKUP(B34,CONFIG!A:A,CONFIG!B:B)} -> ALIMENTOS | E34: FRUTAS
A35: AMENDOA BEN CRUA 110 | B35: AMENDOA | D35: {=XLOOKUP(B35,CONFIG!A:A,CONFIG!B:B)} -> ALIMENTOS
A36: AMENDOA S/C TORRADA | B36: AMENDOA | D36: {=XLOOKUP(B36,CONFIG!A:A,CONFIG!B:B)} -> ALIMENTOS
A37: AMENDOA VILA OLIVA 150GR S/CASCA | B37: AMENDOA | D37: {=XLOOKUP(B37,CONFIG!A:A,CONFIG!B:B)} -> ALIMENTOS
A38: AMIDO MIL MAIZE 200G | B38: AMIDO DE MILHO | D38: {=XLOOKUP(B38,CONFIG!A:A,CONFIG!B:B)} -> ALIMENTOS
A39: ARROZ VASCONCELOS 5KG AG T1 | B39: ARROZ | C39: VASCONCELOS | D39: {=XLOOKUP(B39,CONFIG!A:A,CONFIG!B:B)} -> ALIMENTOS
A40: ASA FGO RESF GRANEL | B40: ASA DE FRANGO | D40: {=XLOOKUP(B40,CONFIG!A:A,CONFIG!B:B)} -> ALIMENTOS
...

Sheet CONFIG
A1: tipo_produto | B1: categoria
A2: ABOBORA | B2: ALIMENTOS
A3: ABSORVENTE | B3: CORPO E BANHO
A4: ACAFRAO | B4: ALIMENTOS
A5: ACEM | B5: ALIMENTOS
A6: ACUCAR CRISTAL | B6: ALIMENTOS
A7: ACUCAR MASCAVO | B7: ALIMENTOS
A8: ACUCAR REFINADO | B8: ALIMENTOS
A9: ADESIVO | B9: OUTROS
A10: AGUA COM GAS | B10: BEBIDAS
A11: ALCATRA | B11: ALIMENTOS
A12: ALFACE | B12: ALIMENTOS
... A246: MOUSSE | B246: ALIMENTOS
